<?xml version="1.0" encoding="utf-8"?>
<!-- This URDF was automatically created by SolidWorks to URDF Exporter! Originally created by Stephen Brawner (brawner@gmail.com) 
     Commit Version: 1.6.0-4-g7f85cfe  Build Version: 1.6.7995.38578
     For more information, please see http://wiki.ros.org/sw_urdf_exporter -->
<robot
  name="lidar2d3d">
  <link
    name="base_link">
    <inertial>
      <origin
        xyz="0.00154740367331764 5.03938146073635E-09 0.0114136928965047"
        rpy="0 0 0" />
      <mass
        value="0.031363358635366" />
      <inertia
        ixx="8.4695791679142E-06"
        ixy="-4.80518896934015E-12"
        ixz="-6.40743927850642E-07"
        iyy="2.61440734807356E-05"
        iyz="-3.82268840532547E-12"
        izz="2.55200519746332E-05" />
    </inertial>
    <visual>
      <origin
        xyz="0 0 0"
        rpy="0 0 0" />
      <geometry>
        <mesh
          filename="package://lidar2d3d/meshes/base_link.STL" />
      </geometry>
      <material
        name="">
        <color
          rgba="1 1 1 1" />
      </material>
    </visual>
    <collision>
      <origin
        xyz="0 0 0"
        rpy="0 0 0" />
      <geometry>
        <mesh
          filename="package://lidar2d3d/meshes/base_link.STL" />
      </geometry>
    </collision>
  </link>
  <link
    name="servo">
    <inertial>
      <origin
        xyz="-3.91864554694088E-10 -0.000303386953667116 0.0131624345466137"
        rpy="0 0 0" />
      <mass
        value="0.00914005029947547" />
      <inertia
        ixx="9.53993205539305E-07"
        ixy="4.32065426697326E-15"
        ixz="3.09285310101611E-14"
        iyy="6.32983778790036E-07"
        iyz="3.52076306474141E-08"
        izz="5.54554013843245E-07" />
    </inertial>
    <visual>
      <origin
        xyz="0 0 0"
        rpy="0 0 0" />
      <geometry>
        <mesh
          filename="package://lidar2d3d/meshes/servo.STL" />
      </geometry>
      <material
        name="">
        <color
          rgba="1 1 1 0.3" />
      </material>
    </visual>
    <collision>
      <origin
        xyz="0 0 0"
        rpy="0 0 0" />
      <geometry>
        <mesh
          filename="package://lidar2d3d/meshes/servo.STL" />
      </geometry>
    </collision>
  </link>
  <joint
    name="base_servo_joint"
    type="fixed">
    <origin
      xyz="-0.0468 -0.000150000000000004 0.026"
      rpy="-1.5707963267949 0 -1.5707963267949" />
    <parent
      link="base_link" />
    <child
      link="servo" />
    <axis
      xyz="0 0 0" />
  </joint>
  <link
    name="lidar_base">
    <inertial>
      <origin
        xyz="-0.00015 0.0048347 0.023842"
        rpy="0 0 0" />
      <mass
        value="0.019119" />
      <inertia
        ixx="6.2993E-06"
        ixy="-5.971E-22"
        ixz="-2.7796E-08"
        iyy="7.9061E-06"
        iyz="4.086E-08"
        izz="2.8542E-06" />
    </inertial>
    <visual>
      <origin
        xyz="0 0 0"
        rpy="0 0 0" />
      <geometry>
        <mesh
          filename="package://lidar2d3d/meshes/lidar_base.STL" />
      </geometry>
      <material
        name="">
        <color
          rgba="1 1 1 1" />
      </material>
    </visual>
    <collision>
      <origin
        xyz="0 0 0"
        rpy="0 0 0" />
      <geometry>
        <mesh
          filename="package://lidar2d3d/meshes/lidar_base.STL" />
      </geometry>
    </collision>
  </link>
  <joint
    name="servo_joint"
    type="revolute">
    <origin
      xyz="0 -0.00515 0.0282"
      rpy="0 0 0" />
    <parent
      link="servo" />
    <child
      link="lidar_base" />
    <axis
      xyz="0 0 -1" />
    <limit
      lower="-1.57"
      upper="1.57"
      effort="10"
      velocity="1" />
  </joint>
  <link
    name="lidar">
    <inertial>
      <origin
        xyz="0 -5.20417042793042E-18 0.0154998143571672"
        rpy="0 0 0" />
      <mass
        value="0.0417717623404389" />
      <inertia
        ixx="7.99971570408385E-06"
        ixy="8.4246422382609E-08"
        ixz="-4.11899425993673E-22"
        iyy="7.99971570408385E-06"
        iyz="-2.72771439271018E-22"
        izz="8.56330292733621E-06" />
    </inertial>
    <visual>
      <origin
        xyz="0 0 0"
        rpy="0 0 0" />
      <geometry>
        <mesh
          filename="package://lidar2d3d/meshes/lidar.STL" />
      </geometry>
      <material
        name="">
        <color
          rgba="1 1 1 1" />
      </material>
    </visual>
    <collision>
      <origin
        xyz="0 0 0"
        rpy="0 0 0" />
      <geometry>
        <mesh
          filename="package://lidar2d3d/meshes/lidar.STL" />
      </geometry>
    </collision>
  </link>
  <joint
    name="lidar_joint"
    type="fixed">
    <origin
      xyz="-0.000150000000000004 0.00665 0.0234"
      rpy="1.5707963267949 0 0" />
    <parent
      link="lidar_base" />
    <child
      link="lidar" />
    <axis
      xyz="0 0 0" />
  </joint>
</robot>